<?xml version="1.0" ?>
<!-- =================================================================================== -->
<!-- |    This document was autogenerated by xacro from src/mobile_robot/model/robot.xacro | -->
<!-- |    EDITING THIS FILE BY HAND IS NOT RECOMMENDED                                 | -->
<!-- =================================================================================== -->
<robot name="ackerman_drive_robot">
  <!-- Leg mass (kg) -->
  <!-- Base Link (World Reference) -->
  <!-- The base_link serves as the fixed reference frame for the robot model -->
  <link name="base_link"/>
  <!-- BASE_FOOTPRINT LINK -->
  <joint name="base_footprint_joint" type="fixed">
    <parent link="base_link"/>
    <child link="base_footprint"/>
    <origin rpy="0 0 0" xyz="0 0 0"/>
  </joint>
  <link name="base_footprint">
  </link>
  <!-- Body Link -->
  <link name="body_link">
    <inertial>
      <origin rpy="0 0 0" xyz="0 0 0"/>
      <mass value="20.0"/>
      <inertia ixx="1.8166666666666667" ixy="0.0" ixz="0.0" iyy="5.069206666666666" iyz="0.0" izz="6.585873333333333"/>
    </inertial>
    <visual>
      <origin rpy="0 0 0" xyz="0 0 0"/>
      <geometry>
        <box size="1.718 1.0 0.3"/>
      </geometry>
      <material name="blue">
        <color rgba="0 0 1 1"/>
        <!-- Blue for visibility -->
      </material>
    </visual>
    <collision>
      <origin rpy="0 0 0" xyz="0 0 0"/>
      <geometry>
        <box size="1.718 1.0 0.3"/>
      </geometry>
    </collision>
  </link>
  <!-- imu -->
  <link name="imu_link">
    <inertial>
      <mass value="0.1"/>
      <inertia ixx="0.001" ixy="0.0" ixz="0.0" iyy="0.001" iyz="0.0" izz="0.001"/>
    </inertial>
    <visual>
      <geometry>
        <box size="0.02 0.02 0.02"/>
      </geometry>
      <material name="white">
        <color rgba="1 1 1 1"/>
      </material>
    </visual>
  </link>
  <joint name="imu_joint" type="fixed">
    <parent link="base_link"/>
    <child link="imu_link"/>
    <origin rpy="0 0 0" xyz="0 0 0.1"/>
  </joint>
  <!-- Fixed joint connecting the base_link to the body_link -->
  <joint name="body_joint" type="fixed">
    <parent link="base_link"/>
    <child link="body_link"/>
    <origin rpy="0 0 0" xyz="0 0 0.915"/>
  </joint>
  <!-- Leg Link -->
  <link name="fl_leg">
    <inertial>
      <origin rpy="0 0 0" xyz="0 0 -0.265"/>
      <mass value="10.0"/>
      <inertia ixx="0.23541666666666666" ixy="0.0" ixz="0.0" iyy="0.23708333333333334" iyz="0.0" izz="0.004333333333333333"/>
    </inertial>
    <visual>
      <origin rpy="0 0 0" xyz="0 0 -0.265"/>
      <geometry>
        <box size="0.06 0.04 0.53"/>
      </geometry>
      <material name="gray">
        <color rgba="0.5 0.5 0.5 1"/>
        <!-- Gray for visibility -->
      </material>
    </visual>
    <collision>
      <origin rpy="0 0 0" xyz="0 0 -0.265"/>
      <geometry>
        <box size="0.06 0.04 0.53"/>
      </geometry>
    </collision>
  </link>
  <!-- Fixed joint to attach the leg to the body link -->
  <joint name="fl_leg_joint" type="fixed">
    <parent link="body_link"/>
    <child link="fl_leg"/>
    <origin rpy="0 -0.2617993877991494 0" xyz="0.54 0.5 -0.15"/>
  </joint>
  <!-- Wheel Link -->
  <link name="fl_wheel">
    <inertial>
      <!-- Wheel inertial parameters: rotated so that cylinder axis is along the proper direction -->
      <origin rpy="1.5707963267948966 0 1.5707963267948966" xyz="0 0 0"/>
      <mass value="1.0"/>
      <inertia ixx="0.01864633333333333" ixy="0.0" ixz="0.0" iyy="0.01864633333333333" iyz="0.0" izz="0.027612499999999998"/>
    </inertial>
    <visual>
      <origin rpy="1.5707963267948966 0 1.5707963267948966" xyz="0 0 0"/>
      <geometry>
        <cylinder length="0.241" radius="0.235"/>
      </geometry>
      <material name="black">
        <color rgba="0 0 0 1"/>
        <!-- Black for visibility -->
      </material>
    </visual>
    <collision>
      <origin rpy="1.5707963267948966 0 1.5707963267948966 " xyz="0 0 0"/>
      <geometry>
        <cylinder length="0.241" radius="0.235"/>
      </geometry>
    </collision>
  </link>
  <link name="fl_steering_link">
    <!-- Inertial properties: Minimal mass and inertia since this is a lightweight steering component. -->
    <inertial>
      <mass value="0.1"/>
      <!-- Simple inertia values (small, uniform) for simulation stability. -->
      <inertia ixx="0.001" ixy="0.0" ixz="0.0" iyy="0.001" iyz="0.0" izz="0.001"/>
    </inertial>
    <visual>
      <origin rpy="1.5707963267948966 0 1.5707963267948966" xyz="0 0 0"/>
      <geometry>
        <cylinder length="0.01" radius="0.01"/>
      </geometry>
      <material name="invisible"/>
    </visual>
  </link>
  <!-- FRONT WHEELS-->
  <!-- Steering Joint: Allows the steering link to rotate (steer) around the vertical axis. -->
  <joint name="fl_steering_joint" type="revolute">
    <parent link="fl_leg"/>
    <!-- Parent is the leg link. -->
    <child link="fl_steering_link"/>
    <!-- Child is the steering link. -->
    <origin rpy="0 0.2617993877991494 0" xyz="0 0 -0.53"/>
    <!-- Positioned at the bottom of the leg (z offset). -->
    <axis xyz="0 0 1"/>
    <!-- Rotation axis is vertical (z-axis) for steering left/right. -->
    <!-- Limits: Steering angle range. effort, and velocity constraints. -->
    <limit effort="100000.0" lower="-0.4" upper="0.4" velocity="10.0"/>
    <dynamics damping="0.2"/>
  </joint>
  <!-- Joint connecting steering and the wheel -->
  <joint name="fl_wheel_joint" type="continuous">
    <parent link="fl_steering_link"/>
    <child link="fl_wheel"/>
    <origin rpy="0 0 1.5707963267948966" xyz="0 0.15 -0.0"/>
    <!-- WRONG   ${-leg_angle} -->
    <axis xyz="1 0 0"/>
    <dynamics damping="0.2"/>
  </joint>
  <!-- Leg Link -->
  <link name="fr_leg">
    <inertial>
      <origin rpy="0 0 0" xyz="0 0 -0.265"/>
      <mass value="10.0"/>
      <inertia ixx="0.23541666666666666" ixy="0.0" ixz="0.0" iyy="0.23708333333333334" iyz="0.0" izz="0.004333333333333333"/>
    </inertial>
    <visual>
      <origin rpy="0 0 0" xyz="0 0 -0.265"/>
      <geometry>
        <box size="0.06 0.04 0.53"/>
      </geometry>
      <material name="gray">
        <color rgba="0.5 0.5 0.5 1"/>
        <!-- Gray for visibility -->
      </material>
    </visual>
    <collision>
      <origin rpy="0 0 0" xyz="0 0 -0.265"/>
      <geometry>
        <box size="0.06 0.04 0.53"/>
      </geometry>
    </collision>
  </link>
  <!-- Fixed joint to attach the leg to the body link -->
  <joint name="fr_leg_joint" type="fixed">
    <parent link="body_link"/>
    <child link="fr_leg"/>
    <origin rpy="0 -0.2617993877991494 0" xyz="0.54 -0.5 -0.15"/>
  </joint>
  <!-- Wheel Link -->
  <link name="fr_wheel">
    <inertial>
      <!-- Wheel inertial parameters: rotated so that cylinder axis is along the proper direction -->
      <origin rpy="1.5707963267948966 0 1.5707963267948966" xyz="0 0 0"/>
      <mass value="1.0"/>
      <inertia ixx="0.01864633333333333" ixy="0.0" ixz="0.0" iyy="0.01864633333333333" iyz="0.0" izz="0.027612499999999998"/>
    </inertial>
    <visual>
      <origin rpy="1.5707963267948966 0 1.5707963267948966" xyz="0 0 0"/>
      <geometry>
        <cylinder length="0.241" radius="0.235"/>
      </geometry>
      <material name="black">
        <color rgba="0 0 0 1"/>
        <!-- Black for visibility -->
      </material>
    </visual>
    <collision>
      <origin rpy="1.5707963267948966 0 1.5707963267948966 " xyz="0 0 0"/>
      <geometry>
        <cylinder length="0.241" radius="0.235"/>
      </geometry>
    </collision>
  </link>
  <link name="fr_steering_link">
    <!-- Inertial properties: Minimal mass and inertia since this is a lightweight steering component. -->
    <inertial>
      <mass value="0.1"/>
      <!-- Simple inertia values (small, uniform) for simulation stability. -->
      <inertia ixx="0.001" ixy="0.0" ixz="0.0" iyy="0.001" iyz="0.0" izz="0.001"/>
    </inertial>
    <visual>
      <origin rpy="1.5707963267948966 0 1.5707963267948966" xyz="0 0 0"/>
      <geometry>
        <cylinder length="0.01" radius="0.01"/>
      </geometry>
      <material name="invisible"/>
    </visual>
  </link>
  <!-- FRONT WHEELS-->
  <!-- Steering Joint: Allows the steering link to rotate (steer) around the vertical axis. -->
  <joint name="fr_steering_joint" type="revolute">
    <parent link="fr_leg"/>
    <!-- Parent is the leg link. -->
    <child link="fr_steering_link"/>
    <!-- Child is the steering link. -->
    <origin rpy="0 0.2617993877991494 0" xyz="0 0 -0.53"/>
    <!-- Positioned at the bottom of the leg (z offset). -->
    <axis xyz="0 0 1"/>
    <!-- Rotation axis is vertical (z-axis) for steering left/right. -->
    <!-- Limits: Steering angle range. effort, and velocity constraints. -->
    <limit effort="100000.0" lower="-0.4" upper="0.4" velocity="10.0"/>
    <dynamics damping="0.2"/>
  </joint>
  <!-- Joint connecting steering and the wheel -->
  <joint name="fr_wheel_joint" type="continuous">
    <parent link="fr_steering_link"/>
    <child link="fr_wheel"/>
    <origin rpy="0 0 1.5707963267948966" xyz="0 -0.15 -0.0"/>
    <!-- WRONG   ${-leg_angle}-->
    <axis xyz="1 0 0"/>
    <dynamics damping="0.2"/>
  </joint>
  <!-- Leg Link -->
  <link name="bl_leg">
    <inertial>
      <origin rpy="0 0 0" xyz="0 0 -0.265"/>
      <mass value="10.0"/>
      <inertia ixx="0.23541666666666666" ixy="0.0" ixz="0.0" iyy="0.23708333333333334" iyz="0.0" izz="0.004333333333333333"/>
    </inertial>
    <visual>
      <origin rpy="0 0 0" xyz="0 0 -0.265"/>
      <geometry>
        <box size="0.06 0.04 0.53"/>
      </geometry>
      <material name="gray">
        <color rgba="0.5 0.5 0.5 1"/>
        <!-- Gray for visibility -->
      </material>
    </visual>
    <collision>
      <origin rpy="0 0 0" xyz="0 0 -0.265"/>
      <geometry>
        <box size="0.06 0.04 0.53"/>
      </geometry>
    </collision>
  </link>
  <!-- Fixed joint to attach the leg to the body link -->
  <joint name="bl_leg_joint" type="fixed">
    <parent link="body_link"/>
    <child link="bl_leg"/>
    <origin rpy="0 0.2617993877991494 0" xyz="-0.54 0.5 -0.15"/>
  </joint>
  <!-- Wheel Link -->
  <link name="bl_wheel">
    <inertial>
      <!-- Wheel inertial parameters: rotated so that cylinder axis is along the proper direction -->
      <origin rpy="1.5707963267948966 0 1.5707963267948966" xyz="0 0 0"/>
      <mass value="1.0"/>
      <inertia ixx="0.01864633333333333" ixy="0.0" ixz="0.0" iyy="0.01864633333333333" iyz="0.0" izz="0.027612499999999998"/>
    </inertial>
    <visual>
      <origin rpy="1.5707963267948966 0 1.5707963267948966" xyz="0 0 0"/>
      <geometry>
        <cylinder length="0.241" radius="0.235"/>
      </geometry>
      <material name="black">
        <color rgba="0 0 0 1"/>
        <!-- Black for visibility -->
      </material>
    </visual>
    <collision>
      <origin rpy="1.5707963267948966 0 1.5707963267948966 " xyz="0 0 0"/>
      <geometry>
        <cylinder length="0.241" radius="0.235"/>
      </geometry>
    </collision>
  </link>
  <joint name="bl_wheel_joint" type="continuous">
    <parent link="bl_leg"/>
    <child link="bl_wheel"/>
    <origin rpy="0 0 1.5707963267948966" xyz="0 0.15 -0.53"/>
    <axis xyz="1 0 0"/>
    <dynamics damping="0.01"/>
  </joint>
  <!-- Leg Link -->
  <link name="br_leg">
    <inertial>
      <origin rpy="0 0 0" xyz="0 0 -0.265"/>
      <mass value="10.0"/>
      <inertia ixx="0.23541666666666666" ixy="0.0" ixz="0.0" iyy="0.23708333333333334" iyz="0.0" izz="0.004333333333333333"/>
    </inertial>
    <visual>
      <origin rpy="0 0 0" xyz="0 0 -0.265"/>
      <geometry>
        <box size="0.06 0.04 0.53"/>
      </geometry>
      <material name="gray">
        <color rgba="0.5 0.5 0.5 1"/>
        <!-- Gray for visibility -->
      </material>
    </visual>
    <collision>
      <origin rpy="0 0 0" xyz="0 0 -0.265"/>
      <geometry>
        <box size="0.06 0.04 0.53"/>
      </geometry>
    </collision>
  </link>
  <!-- Fixed joint to attach the leg to the body link -->
  <joint name="br_leg_joint" type="fixed">
    <parent link="body_link"/>
    <child link="br_leg"/>
    <origin rpy="0 0.2617993877991494 0" xyz="-0.54 -0.5 -0.15"/>
  </joint>
  <!-- Wheel Link -->
  <link name="br_wheel">
    <inertial>
      <!-- Wheel inertial parameters: rotated so that cylinder axis is along the proper direction -->
      <origin rpy="1.5707963267948966 0 1.5707963267948966" xyz="0 0 0"/>
      <mass value="1.0"/>
      <inertia ixx="0.01864633333333333" ixy="0.0" ixz="0.0" iyy="0.01864633333333333" iyz="0.0" izz="0.027612499999999998"/>
    </inertial>
    <visual>
      <origin rpy="1.5707963267948966 0 1.5707963267948966" xyz="0 0 0"/>
      <geometry>
        <cylinder length="0.241" radius="0.235"/>
      </geometry>
      <material name="black">
        <color rgba="0 0 0 1"/>
        <!-- Black for visibility -->
      </material>
    </visual>
    <collision>
      <origin rpy="1.5707963267948966 0 1.5707963267948966 " xyz="0 0 0"/>
      <geometry>
        <cylinder length="0.241" radius="0.235"/>
      </geometry>
    </collision>
  </link>
  <joint name="br_wheel_joint" type="continuous">
    <parent link="br_leg"/>
    <child link="br_wheel"/>
    <origin rpy="0 0 1.5707963267948966" xyz="0 -0.15 -0.53"/>
    <axis xyz="1 0 0"/>
    <dynamics damping="0.01"/>
  </joint>
  <ros2_control name="GazeboSystem" type="system">
    <hardware>
      <plugin>gz_ros2_control/GazeboSimSystem</plugin>
    </hardware>
    <joint name="fl_steering_joint">
      <command_interface name="position"/>
      <state_interface name="position"/>
      <state_interface name="velocity"/>
    </joint>
    <joint name="fr_steering_joint">
      <command_interface name="position"/>
      <state_interface name="position"/>
      <state_interface name="velocity"/>
    </joint>
    <joint name="bl_wheel_joint">
      <command_interface name="velocity"/>
      <state_interface name="position"/>
      <state_interface name="velocity"/>
    </joint>
    <joint name="br_wheel_joint">
      <command_interface name="velocity"/>
      <state_interface name="position"/>
      <state_interface name="velocity"/>
    </joint>
    <!--To show them in rviz  -->
    <joint name="fl_wheel_joint">
      <command_interface name="velocity"/>
      <state_interface name="position"/>
      <state_interface name="velocity"/>
    </joint>
    <joint name="fr_wheel_joint">
      <command_interface name="velocity"/>
      <state_interface name="position"/>
      <state_interface name="velocity"/>
    </joint>
  </ros2_control>
  <!-- Transmission Elements -->
  <!-- Transmissions map joint commands to actuator commands -->
  <!--
  This defines a transmission between an actuator and a joint.

  - 'SimpleTransmission' assumes a 1:1 mapping (no reduction or gearing).
  - The actuator (fl_wheel_actuator) will control the joint (fl_wheel_joint).
  - Required by ros2_control to map control commands to physical or simulated hardware.
-->
  <transmission name="fl_steering_trans">
    <type>transmission_interface/SimpleTransmission</type>
    <joint name="fl_steering_joint"/>
    <actuator name="fl_steering_actuator"/>
  </transmission>
  <transmission name="fr_steering_trans">
    <type>transmission_interface/SimpleTransmission</type>
    <joint name="fr_steering_joint"/>
    <actuator name="fr_steering_actuator"/>
  </transmission>
  <transmission name="bl_wheel_trans">
    <type>transmission_interface/SimpleTransmission</type>
    <joint name="bl_wheel_joint"/>
    <actuator name="bl_wheel_actuator"/>
  </transmission>
  <transmission name="br_wheel_trans">
    <type>transmission_interface/SimpleTransmission</type>
    <joint name="br_wheel_joint"/>
    <actuator name="br_wheel_actuator"/>
  </transmission>
  <transmission name="fl_wheel_trans">
    <type>transmission_interface/SimpleTransmission</type>
    <joint name="fl_wheel_joint"/>
    <actuator name="fl_wheel_actuator"/>
  </transmission>
  <transmission name="fr_wheel_trans">
    <type>transmission_interface/SimpleTransmission</type>
    <joint name="fr_wheel_joint"/>
    <actuator name="fr_wheel_actuator"/>
  </transmission>
  <!-- Gazebo-Specific Properties -->
  <!-- Body with custom dark grey material -->
  <gazebo reference="body_link">
    <mu1>1.0</mu1>
    <mu2>1.0</mu2>
    <material>
      <ambient>0.1 0.1 0.1 1</ambient>
      <diffuse>0.3 0.3 0.3 1</diffuse>
      <specular>0.5 0.5 0.5 1</specular>
      <emissive>0 0 0 1</emissive>
    </material>
  </gazebo>
  <!-- Legs with matching dark grey material -->
  <gazebo reference="fl_leg">
    <mu1>1.0</mu1>
    <mu2>1.0</mu2>
    <material>
      <ambient>0.1 0.1 0.1 1</ambient>
      <diffuse>0.3 0.3 0.3 1</diffuse>
      <specular>0.5 0.5 0.5 1</specular>
      <emissive>0 0 0 1</emissive>
    </material>
  </gazebo>
  <gazebo reference="fr_leg">
    <mu1>1.0</mu1>
    <mu2>1.0</mu2>
    <material>
      <ambient>0.1 0.1 0.1 1</ambient>
      <diffuse>0.3 0.3 0.3 1</diffuse>
      <specular>0.5 0.5 0.5 1</specular>
      <emissive>0 0 0 1</emissive>
    </material>
  </gazebo>
  <gazebo reference="bl_leg">
    <mu1>1.0</mu1>
    <mu2>1.0</mu2>
    <material>
      <ambient>0.1 0.1 0.1 1</ambient>
      <diffuse>0.3 0.3 0.3 1</diffuse>
      <specular>0.5 0.5 0.5 1</specular>
      <emissive>0 0 0 1</emissive>
    </material>
  </gazebo>
  <gazebo reference="br_leg">
    <mu1>1.0</mu1>
    <mu2>1.0</mu2>
    <material>
      <ambient>0.1 0.1 0.1 1</ambient>
      <diffuse>0.3 0.3 0.3 1</diffuse>
      <specular>0.5 0.5 0.5 1</specular>
      <emissive>0 0 0 1</emissive>
    </material>
  </gazebo>
  <!-- Wheels set to black -->
  <!-- <gazebo reference="fl_wheel">
    <mu1>0.1</mu1>
    <mu2>0.1</mu2>
    <material>Gazebo/Black</material>
  </gazebo>
  <gazebo reference="fr_wheel">
    <mu1>0.1</mu1>
    <mu2>0.1</mu2>
    <material>Gazebo/Black</material>
  </gazebo> -->
  <gazebo reference="fl_wheel">
    <mu1>1</mu1>
    <mu2>1</mu2>
    <material>Gazebo/Black</material>
  </gazebo>
  <gazebo reference="fr_wheel">
    <mu1>1</mu1>
    <mu2>1</mu2>
    <material>Gazebo/Black</material>
  </gazebo>
  <gazebo reference="bl_wheel">
    <mu1>1</mu1>
    <mu2>1</mu2>
    <material>Gazebo/Black</material>
  </gazebo>
  <gazebo reference="br_wheel">
    <mu1>1</mu1>
    <mu2>1</mu2>
    <material>Gazebo/Black</material>
  </gazebo>
  <gazebo>
    <plugin filename="gz-sim-joint-state-publisher-system" name="gz::sim::systems::JointStatePublisher">
      <topic>joint_states</topic>
      <joint_name>fr_steering_joint</joint_name>
      <joint_name>fl_steering_joint</joint_name>
      <joint_name>br_wheel_joint</joint_name>
      <joint_name>bl_wheel_joint</joint_name>
      <joint_name>fl_wheel_joint</joint_name>
      <joint_name>fr_wheel_joint</joint_name>
    </plugin>
  </gazebo>
  <!--                                        
  <gazebo>
      <plugin name="gz_ros2_control::GazeboSimROS2ControlPlugin" filename="libgz_ros2_control-system.so">
          <parameters>$(find articubot_one)/config/my_controllers.yaml</parameters>
          <parameters>$(find articubot_one)/config/gaz_ros2_ctl_use_sim.yaml</parameters>
      </plugin>
  </gazebo> -->
  <gazebo>
    <plugin filename="gz-sim-ackermann-steering-system" name="gz::sim::systems::AckermannSteering">
      <robot_sim_type>gz_ros2_control/GazeboSimSystem</robot_sim_type>
      <odometry_frame>odom</odometry_frame>
      <robot_base_frame>base_link</robot_base_frame>
      <publish_odom>true</publish_odom>
      <tf_topic>/tf</tf_topic>
      <odom_topic>/demo/odom</odom_topic>
      <publish_odom_tf>true</publish_odom_tf>
      <publish_wheel_tf>true</publish_wheel_tf>
      <left_joint>bl_wheel_joint</left_joint>
      <left_joint>fl_wheel_joint</left_joint>
      <right_joint>fr_wheel_joint</right_joint>
      <right_joint>br_wheel_joint</right_joint>
      <left_steering_joint>fl_steering_joint</left_steering_joint>
      <right_steering_joint>fr_steering_joint</right_steering_joint>
      <wheel_separation>1</wheel_separation>
      <wheel_radius>0.235</wheel_radius>
      <kingpin_width>1.0</kingpin_width>
      <topic>cmd_vel</topic>
    </plugin>
  </gazebo>
  <!-- <gazebo>
  <plugin name="gz_ros2_control" filename="libgazebo_ros2_control.so">
    <parameters>$(find mobile_robot)/config/ackermann_controllers.yaml</parameters>
  </plugin>
</gazebo>  -->
  <!-- <gazebo>
  <plugin name="gz::sim::systems::AckermannSteering" filename="gz-sim-ackermann-steering-system">
    <parameters>$(find mobile_robot)/config/ackermann_controllers.yaml</parameters>
  </plugin>
</gazebo>  -->
  <!-- <gazebo reference="imu_link">
    <sensor name="imu_sensor" type="imu">
      <always_on>true</always_on>
      <update_rate>100</update_rate>
      <topic>/demo/imu</topic>  
      <imu>
        <noise>
          <type>gaussian</type>
          <rate>
            <mean>0.0</mean>
            <stddev>0.01</stddev>
          </rate>
          <accel>
            <mean>0.0</mean>
            <stddev>0.05</stddev>
          </accel>
        </noise>
      </imu>
    </sensor>
  </gazebo> -->
  <gazebo reference="imu_link">
    <material>Gazebo/Grey</material>
    <sensor name="imu_sensor" type="imu">
      <always_on>true</always_on>
      <update_rate>250</update_rate>
      <enable_orientation>1</enable_orientation>
      <visualize>true</visualize>
      <topic>imu/data</topic>
      <gz_frame_id>base_link</gz_frame_id>
      <imu>
        <angular_velocity>
          <x>
            <noise type="gaussian">
              <mean>0.0</mean>
              <stddev>2e-4</stddev>
              <bias_mean>0.0000075</bias_mean>
              <bias_stddev>0.0000008</bias_stddev>
            </noise>
          </x>
          <y>
            <noise type="gaussian">
              <mean>0.0</mean>
              <stddev>2e-4</stddev>
              <bias_mean>0.0000075</bias_mean>
              <bias_stddev>0.0000008</bias_stddev>
            </noise>
          </y>
          <z>
            <noise type="gaussian">
              <mean>0.0</mean>
              <stddev>2e-4</stddev>
              <bias_mean>0.0000075</bias_mean>
              <bias_stddev>0.0000008</bias_stddev>
            </noise>
          </z>
        </angular_velocity>
        <linear_acceleration>
          <x>
            <noise type="gaussian">
              <mean>0.0</mean>
              <stddev>1.7e-2</stddev>
              <bias_mean>0.1</bias_mean>
              <bias_stddev>0.001</bias_stddev>
            </noise>
          </x>
          <y>
            <noise type="gaussian">
              <mean>0.0</mean>
              <stddev>1.7e-2</stddev>
              <bias_mean>0.1</bias_mean>
              <bias_stddev>0.001</bias_stddev>
            </noise>
          </y>
          <z>
            <noise type="gaussian">
              <mean>0.0</mean>
              <stddev>1.7e-2</stddev>
              <bias_mean>0.1</bias_mean>
              <bias_stddev>0.001</bias_stddev>
            </noise>
          </z>
        </linear_acceleration>
      </imu>
    </sensor>
  </gazebo>
  <!-- <xacro:include filename="$(find mobile_robot)/description/gps.xacro"/> -->
  <!-- <xacro:include filename="$(find mobile_robot)/description/camera.xacro" />
  <xacro:include filename="$(find mobile_robot)/description/lidar.xacro" /> -->
</robot>
